{
 "cells": [
  {
   "cell_type": "markdown",
   "metadata": {},
   "source": [
    "# Model selection - drop questionnaire items\n",
    "\n",
    "https://www.ncbi.nlm.nih.gov/pmc/articles/PMC5019184/"
   ]
  },
  {
   "cell_type": "markdown",
   "metadata": {},
   "source": [
    "## Environment initialization"
   ]
  },
  {
   "cell_type": "code",
   "execution_count": 16,
   "metadata": {},
   "outputs": [
    {
     "data": {
      "application/javascript": [
       "IPython.notebook.set_autosave_interval(0)"
      ]
     },
     "metadata": {},
     "output_type": "display_data"
    },
    {
     "name": "stdout",
     "output_type": "stream",
     "text": [
      "Autosave disabled\n",
      "The autoreload extension is already loaded. To reload it, use:\n",
      "  %reload_ext autoreload\n"
     ]
    }
   ],
   "source": [
    "from __future__ import division, print_function\n",
    "\n",
    "%autosave 0\n",
    "%matplotlib notebook\n",
    "%load_ext autoreload\n",
    "%autoreload 2\n",
    "\n",
    "import numpy as np\n",
    "import os\n",
    "import sklearn as sk\n",
    "from sklearn import preprocessing\n",
    "import pandas as pd\n",
    "\n",
    "import sys\n",
    "sys.path.append(\"../\")\n",
    "\n",
    "import mod_data\n",
    "import mod_evaluation\n",
    "import mod_compute\n",
    "import mod_viewer\n",
    "import mod_latent"
   ]
  },
  {
   "cell_type": "markdown",
   "metadata": {},
   "source": [
    "## Notebook variables"
   ]
  },
  {
   "cell_type": "code",
   "execution_count": 17,
   "metadata": {},
   "outputs": [],
   "source": [
    "data_path = '../data/source/all_data_wide.csv'\n",
    "\n",
    "metric_eval = 'val_categorical_accuracy'"
   ]
  },
  {
   "cell_type": "markdown",
   "metadata": {},
   "source": [
    "## Execution params"
   ]
  },
  {
   "cell_type": "code",
   "execution_count": 18,
   "metadata": {
    "tags": [
     "parameters"
    ]
   },
   "outputs": [],
   "source": [
    "results_path = 'data/results'\n",
    "\n",
    "q_exc = []\n",
    "\n",
    "metric_id = 'categorical_accuracy_class'\n",
    "\n",
    "model_ref_id = 'linear'\n",
    "model_ref_kwargs = {}\n",
    "\n",
    "scaling = None\n",
    "\n",
    "n_splits = 25\n",
    "drop_max = 120\n",
    "\n",
    "train = 0\n",
    "test_size = 200"
   ]
  },
  {
   "cell_type": "markdown",
   "metadata": {},
   "source": [
    "## Running params"
   ]
  },
  {
   "cell_type": "code",
   "execution_count": 19,
   "metadata": {},
   "outputs": [],
   "source": [
    "model_ref = mod_compute.models[model_ref_id]\n",
    "cache_pre = 'model_'+model_ref_id"
   ]
  },
  {
   "cell_type": "markdown",
   "metadata": {},
   "source": [
    "## Model search"
   ]
  },
  {
   "cell_type": "code",
   "execution_count": 20,
   "metadata": {
    "scrolled": false
   },
   "outputs": [
    {
     "name": "stdout",
     "output_type": "stream",
     "text": [
      "evaluating model_linear_categorical_accuracy_class_25_r0\n"
     ]
    },
    {
     "data": {
      "application/vnd.jupyter.widget-view+json": {
       "model_id": "4ebcc629dd0d49ba89b7c1b0d4aae66a",
       "version_major": 2,
       "version_minor": 0
      },
      "text/plain": [
       "HBox(children=(FloatProgress(value=0.0), Output()))"
      ]
     },
     "metadata": {},
     "output_type": "display_data"
    },
    {
     "name": "stdout",
     "output_type": "stream",
     "text": [
      "drop_q\t drop_sum\tval_acc_m (val_acc_min - val_acc_max)\t name\n",
      "\n"
     ]
    },
    {
     "name": "stderr",
     "output_type": "stream",
     "text": [
      "ERROR:root:Internal Python error in the inspect module.\n",
      "Below is the traceback from this internal error.\n",
      "\n",
      "ERROR:root:Internal Python error in the inspect module.\n",
      "Below is the traceback from this internal error.\n",
      "\n",
      "ERROR:root:Internal Python error in the inspect module.\n",
      "Below is the traceback from this internal error.\n",
      "\n",
      "ERROR:root:Internal Python error in the inspect module.\n",
      "Below is the traceback from this internal error.\n",
      "\n"
     ]
    },
    {
     "name": "stdout",
     "output_type": "stream",
     "text": [
      "Traceback (most recent call last):\n",
      "  File \"/share/tools3/lib/python3.5/site-packages/pandas/core/indexes/base.py\", line 2657, in get_loc\n",
      "    return self._engine.get_loc(key)\n",
      "  File \"pandas/_libs/index.pyx\", line 108, in pandas._libs.index.IndexEngine.get_loc\n",
      "  File \"pandas/_libs/index.pyx\", line 132, in pandas._libs.index.IndexEngine.get_loc\n",
      "  File \"pandas/_libs/hashtable_class_helper.pxi\", line 1601, in pandas._libs.hashtable.PyObjectHashTable.get_item\n",
      "  File \"pandas/_libs/hashtable_class_helper.pxi\", line 1608, in pandas._libs.hashtable.PyObjectHashTable.get_item\n",
      "KeyError: 'PANAS_negative_affect'\n",
      "\n",
      "During handling of the above exception, another exception occurred:\n",
      "\n",
      "Traceback (most recent call last):\n",
      "  File \"/share/tools3/lib/python3.5/site-packages/pandas/core/internals/managers.py\", line 1053, in set\n",
      "    loc = self.items.get_loc(item)\n",
      "  File \"/share/tools3/lib/python3.5/site-packages/pandas/core/indexes/base.py\", line 2659, in get_loc\n",
      "    return self._engine.get_loc(self._maybe_cast_indexer(key))\n",
      "  File \"pandas/_libs/index.pyx\", line 108, in pandas._libs.index.IndexEngine.get_loc\n",
      "  File \"pandas/_libs/index.pyx\", line 132, in pandas._libs.index.IndexEngine.get_loc\n",
      "  File \"pandas/_libs/hashtable_class_helper.pxi\", line 1601, in pandas._libs.hashtable.PyObjectHashTable.get_item\n",
      "  File \"pandas/_libs/hashtable_class_helper.pxi\", line 1608, in pandas._libs.hashtable.PyObjectHashTable.get_item\n",
      "KeyError: 'PANAS_negative_affect'\n",
      "\n",
      "During handling of the above exception, another exception occurred:\n",
      "\n",
      "Traceback (most recent call last):\n",
      "  File \"/share/tools3/lib/python3.5/site-packages/IPython/core/interactiveshell.py\", line 3296, in run_code\n",
      "    exec(code_obj, self.user_global_ns, self.user_ns)\n",
      "  File \"<ipython-input-20-3deb154a6e23>\", line 42, in <module>\n",
      "    **model_ref_kwargs\n",
      "  File \"../mod_compute.py\", line 277, in stats_seq_drop\n",
      "    **model_ref_kwargs\n",
      "  File \"../mod_compute.py\", line 220, in model_q_exc\n",
      "    df_x[q_run], df_y\n",
      "  File \"../mod_compute.py\", line 71, in df_to_model_input\n",
      "    x_train = np.array(mod_data.df_to_s(df_x_train))\n",
      "  File \"../mod_data.py\", line 145, in df_to_s\n",
      "    df_s[s] = np.sum(df[my_q], axis=1)\n",
      "  File \"/share/tools3/lib/python3.5/site-packages/pandas/core/frame.py\", line 3370, in __setitem__\n",
      "    self._set_item(key, value)\n",
      "  File \"/share/tools3/lib/python3.5/site-packages/pandas/core/frame.py\", line 3446, in _set_item\n",
      "    NDFrame._set_item(self, key, value)\n",
      "  File \"/share/tools3/lib/python3.5/site-packages/pandas/core/generic.py\", line 3172, in _set_item\n",
      "    self._data.set(key, value)\n",
      "  File \"/share/tools3/lib/python3.5/site-packages/pandas/core/internals/managers.py\", line 1056, in set\n",
      "    self.insert(len(self.items), item, value)\n",
      "  File \"/share/tools3/lib/python3.5/site-packages/pandas/core/internals/managers.py\", line 1171, in insert\n",
      "    self._blklocs = np.append(self._blklocs, 0)\n",
      "  File \"<__array_function__ internals>\", line 6, in append\n",
      "  File \"/share/tools3/lib/python3.5/site-packages/numpy/lib/function_base.py\", line 4700, in append\n",
      "    return concatenate((arr, values), axis=axis)\n",
      "KeyboardInterrupt\n",
      "\n",
      "During handling of the above exception, another exception occurred:\n",
      "\n",
      "Traceback (most recent call last):\n",
      "  File \"/share/tools3/lib/python3.5/site-packages/IPython/core/interactiveshell.py\", line 2033, in showtraceback\n",
      "    stb = value._render_traceback_()\n",
      "AttributeError: 'KeyboardInterrupt' object has no attribute '_render_traceback_'\n",
      "\n",
      "During handling of the above exception, another exception occurred:\n",
      "\n",
      "Traceback (most recent call last):\n",
      "  File \"/share/tools3/lib/python3.5/site-packages/IPython/core/ultratb.py\", line 1095, in get_records\n",
      "    return _fixed_getinnerframes(etb, number_of_lines_of_context, tb_offset)\n",
      "  File \"/share/tools3/lib/python3.5/site-packages/IPython/core/ultratb.py\", line 313, in wrapped\n",
      "    return f(*args, **kwargs)\n",
      "  File \"/share/tools3/lib/python3.5/site-packages/IPython/core/ultratb.py\", line 347, in _fixed_getinnerframes\n",
      "    records = fix_frame_records_filenames(inspect.getinnerframes(etb, context))\n",
      "  File \"/usr/lib/python3.5/inspect.py\", line 1453, in getinnerframes\n",
      "    frameinfo = (tb.tb_frame,) + getframeinfo(tb, context)\n",
      "  File \"/usr/lib/python3.5/inspect.py\", line 1410, in getframeinfo\n",
      "    filename = getsourcefile(frame) or getfile(frame)\n",
      "  File \"/usr/lib/python3.5/inspect.py\", line 672, in getsourcefile\n",
      "    if getattr(getmodule(object, filename), '__loader__', None) is not None:\n",
      "  File \"/usr/lib/python3.5/inspect.py\", line 701, in getmodule\n",
      "    file = getabsfile(object, _filename)\n",
      "  File \"/usr/lib/python3.5/inspect.py\", line 685, in getabsfile\n",
      "    return os.path.normcase(os.path.abspath(_filename))\n",
      "  File \"/share/tools3/lib/python3.5/posixpath.py\", line 361, in abspath\n",
      "    cwd = os.getcwd()\n",
      "FileNotFoundError: [Errno 2] No such file or directory\n",
      "Traceback (most recent call last):\n",
      "  File \"/share/tools3/lib/python3.5/site-packages/pandas/core/indexes/base.py\", line 2657, in get_loc\n",
      "    return self._engine.get_loc(key)\n",
      "  File \"pandas/_libs/index.pyx\", line 108, in pandas._libs.index.IndexEngine.get_loc\n",
      "  File \"pandas/_libs/index.pyx\", line 132, in pandas._libs.index.IndexEngine.get_loc\n",
      "  File \"pandas/_libs/hashtable_class_helper.pxi\", line 1601, in pandas._libs.hashtable.PyObjectHashTable.get_item\n",
      "  File \"pandas/_libs/hashtable_class_helper.pxi\", line 1608, in pandas._libs.hashtable.PyObjectHashTable.get_item\n",
      "KeyError: 'PANAS_negative_affect'\n",
      "\n",
      "During handling of the above exception, another exception occurred:\n",
      "\n",
      "Traceback (most recent call last):\n",
      "  File \"/share/tools3/lib/python3.5/site-packages/pandas/core/internals/managers.py\", line 1053, in set\n",
      "    loc = self.items.get_loc(item)\n",
      "  File \"/share/tools3/lib/python3.5/site-packages/pandas/core/indexes/base.py\", line 2659, in get_loc\n",
      "    return self._engine.get_loc(self._maybe_cast_indexer(key))\n",
      "  File \"pandas/_libs/index.pyx\", line 108, in pandas._libs.index.IndexEngine.get_loc\n",
      "  File \"pandas/_libs/index.pyx\", line 132, in pandas._libs.index.IndexEngine.get_loc\n",
      "  File \"pandas/_libs/hashtable_class_helper.pxi\", line 1601, in pandas._libs.hashtable.PyObjectHashTable.get_item\n",
      "  File \"pandas/_libs/hashtable_class_helper.pxi\", line 1608, in pandas._libs.hashtable.PyObjectHashTable.get_item\n",
      "KeyError: 'PANAS_negative_affect'\n",
      "\n",
      "During handling of the above exception, another exception occurred:\n",
      "\n",
      "Traceback (most recent call last):\n",
      "  File \"/share/tools3/lib/python3.5/site-packages/IPython/core/interactiveshell.py\", line 3296, in run_code\n",
      "    exec(code_obj, self.user_global_ns, self.user_ns)\n",
      "  File \"<ipython-input-20-3deb154a6e23>\", line 42, in <module>\n",
      "    **model_ref_kwargs\n",
      "  File \"../mod_compute.py\", line 277, in stats_seq_drop\n",
      "    **model_ref_kwargs\n",
      "  File \"../mod_compute.py\", line 220, in model_q_exc\n",
      "    df_x[q_run], df_y\n",
      "  File \"../mod_compute.py\", line 71, in df_to_model_input\n",
      "    x_train = np.array(mod_data.df_to_s(df_x_train))\n",
      "  File \"../mod_data.py\", line 145, in df_to_s\n",
      "    df_s[s] = np.sum(df[my_q], axis=1)\n",
      "  File \"/share/tools3/lib/python3.5/site-packages/pandas/core/frame.py\", line 3370, in __setitem__\n",
      "    self._set_item(key, value)\n",
      "  File \"/share/tools3/lib/python3.5/site-packages/pandas/core/frame.py\", line 3446, in _set_item\n",
      "    NDFrame._set_item(self, key, value)\n",
      "  File \"/share/tools3/lib/python3.5/site-packages/pandas/core/generic.py\", line 3172, in _set_item\n",
      "    self._data.set(key, value)\n",
      "  File \"/share/tools3/lib/python3.5/site-packages/pandas/core/internals/managers.py\", line 1056, in set\n",
      "    self.insert(len(self.items), item, value)\n",
      "  File \"/share/tools3/lib/python3.5/site-packages/pandas/core/internals/managers.py\", line 1171, in insert\n",
      "    self._blklocs = np.append(self._blklocs, 0)\n",
      "  File \"<__array_function__ internals>\", line 6, in append\n",
      "  File \"/share/tools3/lib/python3.5/site-packages/numpy/lib/function_base.py\", line 4700, in append\n",
      "    return concatenate((arr, values), axis=axis)\n",
      "KeyboardInterrupt\n",
      "\n",
      "During handling of the above exception, another exception occurred:\n",
      "\n",
      "Traceback (most recent call last):\n",
      "  File \"/share/tools3/lib/python3.5/site-packages/IPython/core/interactiveshell.py\", line 2033, in showtraceback\n",
      "    stb = value._render_traceback_()\n",
      "AttributeError: 'KeyboardInterrupt' object has no attribute '_render_traceback_'\n",
      "\n",
      "During handling of the above exception, another exception occurred:\n",
      "\n",
      "Traceback (most recent call last):\n",
      "  File \"/share/tools3/lib/python3.5/site-packages/IPython/core/interactiveshell.py\", line 3214, in run_ast_nodes\n",
      "    if (yield from self.run_code(code, result)):\n",
      "  File \"/share/tools3/lib/python3.5/site-packages/IPython/core/interactiveshell.py\", line 3313, in run_code\n",
      "    self.showtraceback(running_compiled_code=True)\n",
      "  File \"/share/tools3/lib/python3.5/site-packages/IPython/core/interactiveshell.py\", line 2036, in showtraceback\n",
      "    value, tb, tb_offset=tb_offset)\n",
      "  File \"/share/tools3/lib/python3.5/site-packages/IPython/core/ultratb.py\", line 1379, in structured_traceback\n",
      "    self, etype, value, tb, tb_offset, number_of_lines_of_context)\n",
      "  File \"/share/tools3/lib/python3.5/site-packages/IPython/core/ultratb.py\", line 1282, in structured_traceback\n",
      "    self, etype, value, tb, tb_offset, number_of_lines_of_context\n",
      "  File \"/share/tools3/lib/python3.5/site-packages/IPython/core/ultratb.py\", line 1144, in structured_traceback\n",
      "    formatted_exceptions += self.prepare_chained_exception_message(evalue.__cause__)\n",
      "TypeError: Can't convert 'list' object to str implicitly\n",
      "\n",
      "During handling of the above exception, another exception occurred:\n",
      "\n",
      "Traceback (most recent call last):\n",
      "  File \"/share/tools3/lib/python3.5/site-packages/IPython/core/interactiveshell.py\", line 2033, in showtraceback\n",
      "    stb = value._render_traceback_()\n",
      "AttributeError: 'TypeError' object has no attribute '_render_traceback_'\n",
      "\n",
      "During handling of the above exception, another exception occurred:\n",
      "\n",
      "Traceback (most recent call last):\n",
      "  File \"/share/tools3/lib/python3.5/site-packages/IPython/core/ultratb.py\", line 1095, in get_records\n",
      "    return _fixed_getinnerframes(etb, number_of_lines_of_context, tb_offset)\n",
      "  File \"/share/tools3/lib/python3.5/site-packages/IPython/core/ultratb.py\", line 313, in wrapped\n",
      "    return f(*args, **kwargs)\n",
      "  File \"/share/tools3/lib/python3.5/site-packages/IPython/core/ultratb.py\", line 347, in _fixed_getinnerframes\n",
      "    records = fix_frame_records_filenames(inspect.getinnerframes(etb, context))\n",
      "  File \"/usr/lib/python3.5/inspect.py\", line 1453, in getinnerframes\n",
      "    frameinfo = (tb.tb_frame,) + getframeinfo(tb, context)\n",
      "  File \"/usr/lib/python3.5/inspect.py\", line 1410, in getframeinfo\n",
      "    filename = getsourcefile(frame) or getfile(frame)\n",
      "  File \"/usr/lib/python3.5/inspect.py\", line 672, in getsourcefile\n",
      "    if getattr(getmodule(object, filename), '__loader__', None) is not None:\n",
      "  File \"/usr/lib/python3.5/inspect.py\", line 701, in getmodule\n",
      "    file = getabsfile(object, _filename)\n",
      "  File \"/usr/lib/python3.5/inspect.py\", line 685, in getabsfile\n",
      "    return os.path.normcase(os.path.abspath(_filename))\n",
      "  File \"/share/tools3/lib/python3.5/posixpath.py\", line 361, in abspath\n",
      "    cwd = os.getcwd()\n",
      "FileNotFoundError: [Errno 2] No such file or directory\n",
      "Traceback (most recent call last):\n",
      "  File \"/share/tools3/lib/python3.5/site-packages/pandas/core/indexes/base.py\", line 2657, in get_loc\n",
      "    return self._engine.get_loc(key)\n",
      "  File \"pandas/_libs/index.pyx\", line 108, in pandas._libs.index.IndexEngine.get_loc\n",
      "  File \"pandas/_libs/index.pyx\", line 132, in pandas._libs.index.IndexEngine.get_loc\n",
      "  File \"pandas/_libs/hashtable_class_helper.pxi\", line 1601, in pandas._libs.hashtable.PyObjectHashTable.get_item\n",
      "  File \"pandas/_libs/hashtable_class_helper.pxi\", line 1608, in pandas._libs.hashtable.PyObjectHashTable.get_item\n",
      "KeyError: 'PANAS_negative_affect'\n",
      "\n",
      "During handling of the above exception, another exception occurred:\n",
      "\n",
      "Traceback (most recent call last):\n",
      "  File \"/share/tools3/lib/python3.5/site-packages/pandas/core/internals/managers.py\", line 1053, in set\n",
      "    loc = self.items.get_loc(item)\n",
      "  File \"/share/tools3/lib/python3.5/site-packages/pandas/core/indexes/base.py\", line 2659, in get_loc\n",
      "    return self._engine.get_loc(self._maybe_cast_indexer(key))\n",
      "  File \"pandas/_libs/index.pyx\", line 108, in pandas._libs.index.IndexEngine.get_loc\n",
      "  File \"pandas/_libs/index.pyx\", line 132, in pandas._libs.index.IndexEngine.get_loc\n",
      "  File \"pandas/_libs/hashtable_class_helper.pxi\", line 1601, in pandas._libs.hashtable.PyObjectHashTable.get_item\n",
      "  File \"pandas/_libs/hashtable_class_helper.pxi\", line 1608, in pandas._libs.hashtable.PyObjectHashTable.get_item\n",
      "KeyError: 'PANAS_negative_affect'\n",
      "\n",
      "During handling of the above exception, another exception occurred:\n",
      "\n",
      "Traceback (most recent call last):\n",
      "  File \"/share/tools3/lib/python3.5/site-packages/IPython/core/interactiveshell.py\", line 3296, in run_code\n",
      "    exec(code_obj, self.user_global_ns, self.user_ns)\n",
      "  File \"<ipython-input-20-3deb154a6e23>\", line 42, in <module>\n",
      "    **model_ref_kwargs\n",
      "  File \"../mod_compute.py\", line 277, in stats_seq_drop\n",
      "    **model_ref_kwargs\n",
      "  File \"../mod_compute.py\", line 220, in model_q_exc\n",
      "    df_x[q_run], df_y\n",
      "  File \"../mod_compute.py\", line 71, in df_to_model_input\n",
      "    x_train = np.array(mod_data.df_to_s(df_x_train))\n",
      "  File \"../mod_data.py\", line 145, in df_to_s\n",
      "    df_s[s] = np.sum(df[my_q], axis=1)\n",
      "  File \"/share/tools3/lib/python3.5/site-packages/pandas/core/frame.py\", line 3370, in __setitem__\n",
      "    self._set_item(key, value)\n",
      "  File \"/share/tools3/lib/python3.5/site-packages/pandas/core/frame.py\", line 3446, in _set_item\n",
      "    NDFrame._set_item(self, key, value)\n",
      "  File \"/share/tools3/lib/python3.5/site-packages/pandas/core/generic.py\", line 3172, in _set_item\n",
      "    self._data.set(key, value)\n",
      "  File \"/share/tools3/lib/python3.5/site-packages/pandas/core/internals/managers.py\", line 1056, in set\n",
      "    self.insert(len(self.items), item, value)\n",
      "  File \"/share/tools3/lib/python3.5/site-packages/pandas/core/internals/managers.py\", line 1171, in insert\n",
      "    self._blklocs = np.append(self._blklocs, 0)\n",
      "  File \"<__array_function__ internals>\", line 6, in append\n",
      "  File \"/share/tools3/lib/python3.5/site-packages/numpy/lib/function_base.py\", line 4700, in append\n",
      "    return concatenate((arr, values), axis=axis)\n",
      "KeyboardInterrupt\n",
      "\n",
      "During handling of the above exception, another exception occurred:\n",
      "\n",
      "Traceback (most recent call last):\n",
      "  File \"/share/tools3/lib/python3.5/site-packages/IPython/core/interactiveshell.py\", line 2033, in showtraceback\n",
      "    stb = value._render_traceback_()\n",
      "AttributeError: 'KeyboardInterrupt' object has no attribute '_render_traceback_'\n",
      "\n",
      "During handling of the above exception, another exception occurred:\n",
      "\n",
      "Traceback (most recent call last):\n",
      "  File \"/share/tools3/lib/python3.5/site-packages/IPython/core/interactiveshell.py\", line 3214, in run_ast_nodes\n",
      "    if (yield from self.run_code(code, result)):\n",
      "  File \"/share/tools3/lib/python3.5/site-packages/IPython/core/interactiveshell.py\", line 3313, in run_code\n",
      "    self.showtraceback(running_compiled_code=True)\n",
      "  File \"/share/tools3/lib/python3.5/site-packages/IPython/core/interactiveshell.py\", line 2036, in showtraceback\n",
      "    value, tb, tb_offset=tb_offset)\n",
      "  File \"/share/tools3/lib/python3.5/site-packages/IPython/core/ultratb.py\", line 1379, in structured_traceback\n",
      "    self, etype, value, tb, tb_offset, number_of_lines_of_context)\n",
      "  File \"/share/tools3/lib/python3.5/site-packages/IPython/core/ultratb.py\", line 1282, in structured_traceback\n",
      "    self, etype, value, tb, tb_offset, number_of_lines_of_context\n",
      "  File \"/share/tools3/lib/python3.5/site-packages/IPython/core/ultratb.py\", line 1144, in structured_traceback\n",
      "    formatted_exceptions += self.prepare_chained_exception_message(evalue.__cause__)\n",
      "TypeError: Can't convert 'list' object to str implicitly\n",
      "\n",
      "During handling of the above exception, another exception occurred:\n",
      "\n",
      "Traceback (most recent call last):\n",
      "  File \"/share/tools3/lib/python3.5/site-packages/IPython/core/interactiveshell.py\", line 2033, in showtraceback\n",
      "    stb = value._render_traceback_()\n",
      "AttributeError: 'TypeError' object has no attribute '_render_traceback_'\n",
      "\n",
      "During handling of the above exception, another exception occurred:\n",
      "\n",
      "Traceback (most recent call last):\n",
      "  File \"/share/tools3/lib/python3.5/site-packages/IPython/core/ultratb.py\", line 1095, in get_records\n",
      "    return _fixed_getinnerframes(etb, number_of_lines_of_context, tb_offset)\n",
      "  File \"/share/tools3/lib/python3.5/site-packages/IPython/core/ultratb.py\", line 313, in wrapped\n",
      "    return f(*args, **kwargs)\n",
      "  File \"/share/tools3/lib/python3.5/site-packages/IPython/core/ultratb.py\", line 347, in _fixed_getinnerframes\n",
      "    records = fix_frame_records_filenames(inspect.getinnerframes(etb, context))\n",
      "  File \"/usr/lib/python3.5/inspect.py\", line 1453, in getinnerframes\n",
      "    frameinfo = (tb.tb_frame,) + getframeinfo(tb, context)\n",
      "  File \"/usr/lib/python3.5/inspect.py\", line 1410, in getframeinfo\n",
      "    filename = getsourcefile(frame) or getfile(frame)\n",
      "  File \"/usr/lib/python3.5/inspect.py\", line 672, in getsourcefile\n",
      "    if getattr(getmodule(object, filename), '__loader__', None) is not None:\n",
      "  File \"/usr/lib/python3.5/inspect.py\", line 701, in getmodule\n",
      "    file = getabsfile(object, _filename)\n",
      "  File \"/usr/lib/python3.5/inspect.py\", line 685, in getabsfile\n",
      "    return os.path.normcase(os.path.abspath(_filename))\n",
      "  File \"/share/tools3/lib/python3.5/posixpath.py\", line 361, in abspath\n",
      "    cwd = os.getcwd()\n",
      "FileNotFoundError: [Errno 2] No such file or directory\n",
      "Traceback (most recent call last):\n",
      "  File \"/share/tools3/lib/python3.5/site-packages/pandas/core/indexes/base.py\", line 2657, in get_loc\n",
      "    return self._engine.get_loc(key)\n",
      "  File \"pandas/_libs/index.pyx\", line 108, in pandas._libs.index.IndexEngine.get_loc\n",
      "  File \"pandas/_libs/index.pyx\", line 132, in pandas._libs.index.IndexEngine.get_loc\n",
      "  File \"pandas/_libs/hashtable_class_helper.pxi\", line 1601, in pandas._libs.hashtable.PyObjectHashTable.get_item\n",
      "  File \"pandas/_libs/hashtable_class_helper.pxi\", line 1608, in pandas._libs.hashtable.PyObjectHashTable.get_item\n",
      "KeyError: 'PANAS_negative_affect'\n",
      "\n",
      "During handling of the above exception, another exception occurred:\n",
      "\n",
      "Traceback (most recent call last):\n",
      "  File \"/share/tools3/lib/python3.5/site-packages/pandas/core/internals/managers.py\", line 1053, in set\n",
      "    loc = self.items.get_loc(item)\n",
      "  File \"/share/tools3/lib/python3.5/site-packages/pandas/core/indexes/base.py\", line 2659, in get_loc\n",
      "    return self._engine.get_loc(self._maybe_cast_indexer(key))\n",
      "  File \"pandas/_libs/index.pyx\", line 108, in pandas._libs.index.IndexEngine.get_loc\n",
      "  File \"pandas/_libs/index.pyx\", line 132, in pandas._libs.index.IndexEngine.get_loc\n",
      "  File \"pandas/_libs/hashtable_class_helper.pxi\", line 1601, in pandas._libs.hashtable.PyObjectHashTable.get_item\n",
      "  File \"pandas/_libs/hashtable_class_helper.pxi\", line 1608, in pandas._libs.hashtable.PyObjectHashTable.get_item\n",
      "KeyError: 'PANAS_negative_affect'\n",
      "\n",
      "During handling of the above exception, another exception occurred:\n",
      "\n",
      "Traceback (most recent call last):\n",
      "  File \"/share/tools3/lib/python3.5/site-packages/IPython/core/interactiveshell.py\", line 3296, in run_code\n",
      "    exec(code_obj, self.user_global_ns, self.user_ns)\n",
      "  File \"<ipython-input-20-3deb154a6e23>\", line 42, in <module>\n",
      "    **model_ref_kwargs\n",
      "  File \"../mod_compute.py\", line 277, in stats_seq_drop\n",
      "    **model_ref_kwargs\n",
      "  File \"../mod_compute.py\", line 220, in model_q_exc\n",
      "    df_x[q_run], df_y\n",
      "  File \"../mod_compute.py\", line 71, in df_to_model_input\n",
      "    x_train = np.array(mod_data.df_to_s(df_x_train))\n",
      "  File \"../mod_data.py\", line 145, in df_to_s\n",
      "    df_s[s] = np.sum(df[my_q], axis=1)\n",
      "  File \"/share/tools3/lib/python3.5/site-packages/pandas/core/frame.py\", line 3370, in __setitem__\n",
      "    self._set_item(key, value)\n",
      "  File \"/share/tools3/lib/python3.5/site-packages/pandas/core/frame.py\", line 3446, in _set_item\n",
      "    NDFrame._set_item(self, key, value)\n",
      "  File \"/share/tools3/lib/python3.5/site-packages/pandas/core/generic.py\", line 3172, in _set_item\n",
      "    self._data.set(key, value)\n",
      "  File \"/share/tools3/lib/python3.5/site-packages/pandas/core/internals/managers.py\", line 1056, in set\n",
      "    self.insert(len(self.items), item, value)\n",
      "  File \"/share/tools3/lib/python3.5/site-packages/pandas/core/internals/managers.py\", line 1171, in insert\n",
      "    self._blklocs = np.append(self._blklocs, 0)\n",
      "  File \"<__array_function__ internals>\", line 6, in append\n",
      "  File \"/share/tools3/lib/python3.5/site-packages/numpy/lib/function_base.py\", line 4700, in append\n",
      "    return concatenate((arr, values), axis=axis)\n",
      "KeyboardInterrupt\n",
      "\n",
      "During handling of the above exception, another exception occurred:\n",
      "\n",
      "Traceback (most recent call last):\n",
      "  File \"/share/tools3/lib/python3.5/site-packages/IPython/core/interactiveshell.py\", line 2033, in showtraceback\n",
      "    stb = value._render_traceback_()\n",
      "AttributeError: 'KeyboardInterrupt' object has no attribute '_render_traceback_'\n",
      "\n",
      "During handling of the above exception, another exception occurred:\n",
      "\n",
      "Traceback (most recent call last):\n",
      "  File \"/share/tools3/lib/python3.5/site-packages/IPython/core/interactiveshell.py\", line 3214, in run_ast_nodes\n",
      "    if (yield from self.run_code(code, result)):\n",
      "  File \"/share/tools3/lib/python3.5/site-packages/IPython/core/interactiveshell.py\", line 3313, in run_code\n",
      "    self.showtraceback(running_compiled_code=True)\n",
      "  File \"/share/tools3/lib/python3.5/site-packages/IPython/core/interactiveshell.py\", line 2036, in showtraceback\n",
      "    value, tb, tb_offset=tb_offset)\n",
      "  File \"/share/tools3/lib/python3.5/site-packages/IPython/core/ultratb.py\", line 1379, in structured_traceback\n",
      "    self, etype, value, tb, tb_offset, number_of_lines_of_context)\n",
      "  File \"/share/tools3/lib/python3.5/site-packages/IPython/core/ultratb.py\", line 1282, in structured_traceback\n",
      "    self, etype, value, tb, tb_offset, number_of_lines_of_context\n",
      "  File \"/share/tools3/lib/python3.5/site-packages/IPython/core/ultratb.py\", line 1144, in structured_traceback\n",
      "    formatted_exceptions += self.prepare_chained_exception_message(evalue.__cause__)\n",
      "TypeError: Can't convert 'list' object to str implicitly\n",
      "\n",
      "During handling of the above exception, another exception occurred:\n",
      "\n",
      "Traceback (most recent call last):\n",
      "  File \"/share/tools3/lib/python3.5/site-packages/IPython/core/interactiveshell.py\", line 2033, in showtraceback\n",
      "    stb = value._render_traceback_()\n",
      "AttributeError: 'TypeError' object has no attribute '_render_traceback_'\n",
      "\n",
      "During handling of the above exception, another exception occurred:\n",
      "\n",
      "Traceback (most recent call last):\n",
      "  File \"/share/tools3/lib/python3.5/site-packages/IPython/core/ultratb.py\", line 1095, in get_records\n",
      "    return _fixed_getinnerframes(etb, number_of_lines_of_context, tb_offset)\n",
      "  File \"/share/tools3/lib/python3.5/site-packages/IPython/core/ultratb.py\", line 313, in wrapped\n",
      "    return f(*args, **kwargs)\n",
      "  File \"/share/tools3/lib/python3.5/site-packages/IPython/core/ultratb.py\", line 347, in _fixed_getinnerframes\n",
      "    records = fix_frame_records_filenames(inspect.getinnerframes(etb, context))\n",
      "  File \"/usr/lib/python3.5/inspect.py\", line 1453, in getinnerframes\n",
      "    frameinfo = (tb.tb_frame,) + getframeinfo(tb, context)\n",
      "  File \"/usr/lib/python3.5/inspect.py\", line 1410, in getframeinfo\n",
      "    filename = getsourcefile(frame) or getfile(frame)\n",
      "  File \"/usr/lib/python3.5/inspect.py\", line 672, in getsourcefile\n",
      "    if getattr(getmodule(object, filename), '__loader__', None) is not None:\n",
      "  File \"/usr/lib/python3.5/inspect.py\", line 701, in getmodule\n",
      "    file = getabsfile(object, _filename)\n",
      "  File \"/usr/lib/python3.5/inspect.py\", line 685, in getabsfile\n",
      "    return os.path.normcase(os.path.abspath(_filename))\n",
      "  File \"/share/tools3/lib/python3.5/posixpath.py\", line 361, in abspath\n",
      "    cwd = os.getcwd()\n",
      "FileNotFoundError: [Errno 2] No such file or directory\n"
     ]
    },
    {
     "ename": "TypeError",
     "evalue": "Can't convert 'list' object to str implicitly",
     "output_type": "error",
     "traceback": [
      "\u001b[0;31m---------------------------------------------------------------------------\u001b[0m",
      "\nDuring handling of the above exception, another exception occurred:\n",
      "\nDuring handling of the above exception, another exception occurred:\n",
      "\nDuring handling of the above exception, another exception occurred:\n",
      "\u001b[0;31mAttributeError\u001b[0m                            Traceback (most recent call last)",
      "\u001b[0;32m/share/tools3/lib/python3.5/site-packages/IPython/core/interactiveshell.py\u001b[0m in \u001b[0;36mshowtraceback\u001b[0;34m(self, exc_tuple, filename, tb_offset, exception_only, running_compiled_code)\u001b[0m\n\u001b[1;32m   2032\u001b[0m                         \u001b[0;31m# in the engines. This should return a list of strings.\u001b[0m\u001b[0;34m\u001b[0m\u001b[0;34m\u001b[0m\u001b[0m\n\u001b[0;32m-> 2033\u001b[0;31m                         \u001b[0mstb\u001b[0m \u001b[0;34m=\u001b[0m \u001b[0mvalue\u001b[0m\u001b[0;34m.\u001b[0m\u001b[0m_render_traceback_\u001b[0m\u001b[0;34m(\u001b[0m\u001b[0;34m)\u001b[0m\u001b[0;34m\u001b[0m\u001b[0m\n\u001b[0m\u001b[1;32m   2034\u001b[0m                     \u001b[0;32mexcept\u001b[0m \u001b[0mException\u001b[0m\u001b[0;34m:\u001b[0m\u001b[0;34m\u001b[0m\u001b[0m\n",
      "\u001b[0;31mAttributeError\u001b[0m: 'KeyboardInterrupt' object has no attribute '_render_traceback_'",
      "\nDuring handling of the above exception, another exception occurred:\n",
      "\u001b[0;31mTypeError\u001b[0m                                 Traceback (most recent call last)",
      "\u001b[0;32m/share/tools3/lib/python3.5/site-packages/IPython/core/interactiveshell.py\u001b[0m in \u001b[0;36mrun_code\u001b[0;34m(self, code_obj, result, async_)\u001b[0m\n\u001b[1;32m   3311\u001b[0m             \u001b[0;32mif\u001b[0m \u001b[0mresult\u001b[0m \u001b[0;32mis\u001b[0m \u001b[0;32mnot\u001b[0m \u001b[0;32mNone\u001b[0m\u001b[0;34m:\u001b[0m\u001b[0;34m\u001b[0m\u001b[0m\n\u001b[1;32m   3312\u001b[0m                 \u001b[0mresult\u001b[0m\u001b[0;34m.\u001b[0m\u001b[0merror_in_exec\u001b[0m \u001b[0;34m=\u001b[0m \u001b[0msys\u001b[0m\u001b[0;34m.\u001b[0m\u001b[0mexc_info\u001b[0m\u001b[0;34m(\u001b[0m\u001b[0;34m)\u001b[0m\u001b[0;34m[\u001b[0m\u001b[0;36m1\u001b[0m\u001b[0;34m]\u001b[0m\u001b[0;34m\u001b[0m\u001b[0m\n\u001b[0;32m-> 3313\u001b[0;31m             \u001b[0mself\u001b[0m\u001b[0;34m.\u001b[0m\u001b[0mshowtraceback\u001b[0m\u001b[0;34m(\u001b[0m\u001b[0mrunning_compiled_code\u001b[0m\u001b[0;34m=\u001b[0m\u001b[0;32mTrue\u001b[0m\u001b[0;34m)\u001b[0m\u001b[0;34m\u001b[0m\u001b[0m\n\u001b[0m\u001b[1;32m   3314\u001b[0m         \u001b[0;32melse\u001b[0m\u001b[0;34m:\u001b[0m\u001b[0;34m\u001b[0m\u001b[0m\n\u001b[1;32m   3315\u001b[0m             \u001b[0moutflag\u001b[0m \u001b[0;34m=\u001b[0m \u001b[0;32mFalse\u001b[0m\u001b[0;34m\u001b[0m\u001b[0m\n",
      "\u001b[0;32m/share/tools3/lib/python3.5/site-packages/IPython/core/interactiveshell.py\u001b[0m in \u001b[0;36mshowtraceback\u001b[0;34m(self, exc_tuple, filename, tb_offset, exception_only, running_compiled_code)\u001b[0m\n\u001b[1;32m   2034\u001b[0m                     \u001b[0;32mexcept\u001b[0m \u001b[0mException\u001b[0m\u001b[0;34m:\u001b[0m\u001b[0;34m\u001b[0m\u001b[0m\n\u001b[1;32m   2035\u001b[0m                         stb = self.InteractiveTB.structured_traceback(etype,\n\u001b[0;32m-> 2036\u001b[0;31m                                             value, tb, tb_offset=tb_offset)\n\u001b[0m\u001b[1;32m   2037\u001b[0m \u001b[0;34m\u001b[0m\u001b[0m\n\u001b[1;32m   2038\u001b[0m                     \u001b[0mself\u001b[0m\u001b[0;34m.\u001b[0m\u001b[0m_showtraceback\u001b[0m\u001b[0;34m(\u001b[0m\u001b[0metype\u001b[0m\u001b[0;34m,\u001b[0m \u001b[0mvalue\u001b[0m\u001b[0;34m,\u001b[0m \u001b[0mstb\u001b[0m\u001b[0;34m)\u001b[0m\u001b[0;34m\u001b[0m\u001b[0m\n",
      "\u001b[0;32m/share/tools3/lib/python3.5/site-packages/IPython/core/ultratb.py\u001b[0m in \u001b[0;36mstructured_traceback\u001b[0;34m(self, etype, value, tb, tb_offset, number_of_lines_of_context)\u001b[0m\n\u001b[1;32m   1377\u001b[0m         \u001b[0mself\u001b[0m\u001b[0;34m.\u001b[0m\u001b[0mtb\u001b[0m \u001b[0;34m=\u001b[0m \u001b[0mtb\u001b[0m\u001b[0;34m\u001b[0m\u001b[0m\n\u001b[1;32m   1378\u001b[0m         return FormattedTB.structured_traceback(\n\u001b[0;32m-> 1379\u001b[0;31m             self, etype, value, tb, tb_offset, number_of_lines_of_context)\n\u001b[0m\u001b[1;32m   1380\u001b[0m \u001b[0;34m\u001b[0m\u001b[0m\n\u001b[1;32m   1381\u001b[0m \u001b[0;34m\u001b[0m\u001b[0m\n",
      "\u001b[0;32m/share/tools3/lib/python3.5/site-packages/IPython/core/ultratb.py\u001b[0m in \u001b[0;36mstructured_traceback\u001b[0;34m(self, etype, value, tb, tb_offset, number_of_lines_of_context)\u001b[0m\n\u001b[1;32m   1280\u001b[0m             \u001b[0;31m# Verbose modes need a full traceback\u001b[0m\u001b[0;34m\u001b[0m\u001b[0;34m\u001b[0m\u001b[0m\n\u001b[1;32m   1281\u001b[0m             return VerboseTB.structured_traceback(\n\u001b[0;32m-> 1282\u001b[0;31m                 \u001b[0mself\u001b[0m\u001b[0;34m,\u001b[0m \u001b[0metype\u001b[0m\u001b[0;34m,\u001b[0m \u001b[0mvalue\u001b[0m\u001b[0;34m,\u001b[0m \u001b[0mtb\u001b[0m\u001b[0;34m,\u001b[0m \u001b[0mtb_offset\u001b[0m\u001b[0;34m,\u001b[0m \u001b[0mnumber_of_lines_of_context\u001b[0m\u001b[0;34m\u001b[0m\u001b[0m\n\u001b[0m\u001b[1;32m   1283\u001b[0m             )\n\u001b[1;32m   1284\u001b[0m         \u001b[0;32melif\u001b[0m \u001b[0mmode\u001b[0m \u001b[0;34m==\u001b[0m \u001b[0;34m'Minimal'\u001b[0m\u001b[0;34m:\u001b[0m\u001b[0;34m\u001b[0m\u001b[0m\n",
      "\u001b[0;32m/share/tools3/lib/python3.5/site-packages/IPython/core/ultratb.py\u001b[0m in \u001b[0;36mstructured_traceback\u001b[0;34m(self, etype, evalue, etb, tb_offset, number_of_lines_of_context)\u001b[0m\n\u001b[1;32m   1142\u001b[0m         \u001b[0mexception\u001b[0m \u001b[0;34m=\u001b[0m \u001b[0mself\u001b[0m\u001b[0;34m.\u001b[0m\u001b[0mget_parts_of_chained_exception\u001b[0m\u001b[0;34m(\u001b[0m\u001b[0mevalue\u001b[0m\u001b[0;34m)\u001b[0m\u001b[0;34m\u001b[0m\u001b[0m\n\u001b[1;32m   1143\u001b[0m         \u001b[0;32mif\u001b[0m \u001b[0mexception\u001b[0m\u001b[0;34m:\u001b[0m\u001b[0;34m\u001b[0m\u001b[0m\n\u001b[0;32m-> 1144\u001b[0;31m             \u001b[0mformatted_exceptions\u001b[0m \u001b[0;34m+=\u001b[0m \u001b[0mself\u001b[0m\u001b[0;34m.\u001b[0m\u001b[0mprepare_chained_exception_message\u001b[0m\u001b[0;34m(\u001b[0m\u001b[0mevalue\u001b[0m\u001b[0;34m.\u001b[0m\u001b[0m__cause__\u001b[0m\u001b[0;34m)\u001b[0m\u001b[0;34m\u001b[0m\u001b[0m\n\u001b[0m\u001b[1;32m   1145\u001b[0m             \u001b[0metype\u001b[0m\u001b[0;34m,\u001b[0m \u001b[0mevalue\u001b[0m\u001b[0;34m,\u001b[0m \u001b[0metb\u001b[0m \u001b[0;34m=\u001b[0m \u001b[0mexception\u001b[0m\u001b[0;34m\u001b[0m\u001b[0m\n\u001b[1;32m   1146\u001b[0m         \u001b[0;32melse\u001b[0m\u001b[0;34m:\u001b[0m\u001b[0;34m\u001b[0m\u001b[0m\n",
      "\u001b[0;31mTypeError\u001b[0m: Can't convert 'list' object to str implicitly"
     ]
    }
   ],
   "source": [
    "for train_val_random in range(50):\n",
    "    \n",
    "    cache_post = str(n_splits) + '_r'+str(train_val_random)\n",
    "\n",
    "    cache_sig = mod_evaluation.cache_sig_gen(\n",
    "        metric_id, \n",
    "        cache_pre=cache_pre,\n",
    "        cache_post=cache_post\n",
    "    )\n",
    "\n",
    "    print('evaluating', cache_sig)\n",
    "\n",
    "    df_data = pd.read_csv(data_path)\n",
    "\n",
    "    _, logits = mod_latent.modelPP(df_data[mod_latent.s_latent_ref])\n",
    "\n",
    "    df_data[mod_data.logits_ref] = pd.DataFrame(logits)\n",
    "    \n",
    "    df_data = df_data[df_data['train']==train]\n",
    "    \n",
    "    df_train, df_val = sk.model_selection.train_test_split(\n",
    "        df_data,\n",
    "        test_size=test_size,\n",
    "        random_state=train_val_random,\n",
    "        shuffle=True,\n",
    "        stratify=np.argmax(np.array(df_data[mod_data.logits_ref]), axis=1)\n",
    "    )\n",
    "\n",
    "    df_train_val = (df_train, df_val)\n",
    "\n",
    "    df_x_train, df_y_train, df_x_val, df_y_val = mod_data.load_data_df(df_train_val=df_train_val)\n",
    "\n",
    "    stats_best, info_best = mod_compute.stats_seq_drop(\n",
    "        metric_id,\n",
    "        model_ref,\n",
    "        df_x_train,\n",
    "        df_y_train,\n",
    "        q_exc_init=q_exc, \n",
    "        drop_max=drop_max,\n",
    "        n_splits=n_splits,\n",
    "        metric_eval=metric_eval,\n",
    "        **model_ref_kwargs\n",
    "    )\n",
    "\n",
    "    ## Model validation\n",
    "    stats_val = {}\n",
    "\n",
    "    for model_id in info_best:\n",
    "\n",
    "        q_sel = mod_compute.get_q_sel(info_best[model_id]['q_exc'])\n",
    "\n",
    "        x_train, y_train, x_val, y_val = mod_compute.df_to_model_input(\n",
    "            df_x_train[q_sel], df_y_train, df_x_val[q_sel], df_y_val\n",
    "        )\n",
    "\n",
    "        _, my_stats =  mod_compute.model_train(\n",
    "            x_train, y_train, x_val, y_val, \n",
    "            model_ref,\n",
    "            **model_ref_kwargs\n",
    "        )\n",
    "\n",
    "        stats_val[model_id] = [my_stats]\n",
    "\n",
    "    ## Save results\n",
    "    if not os.path.isdir(results_path):\n",
    "        os.mkdir(results_path)\n",
    "\n",
    "    results = {\n",
    "        'info': info_best,\n",
    "        'stats': stats_best,\n",
    "        'stats_val': stats_val,\n",
    "    }\n",
    "\n",
    "    mod_evaluation.to_cache(cache_sig, results_path, results)"
   ]
  }
 ],
 "metadata": {
  "kernelspec": {
   "display_name": "Python 3",
   "language": "python",
   "name": "python3"
  },
  "language_info": {
   "codemirror_mode": {
    "name": "ipython",
    "version": 3
   },
   "file_extension": ".py",
   "mimetype": "text/x-python",
   "name": "python",
   "nbconvert_exporter": "python",
   "pygments_lexer": "ipython3",
   "version": "3.5.2"
  }
 },
 "nbformat": 4,
 "nbformat_minor": 2
}
